<robot name = "robot">
    <link name="link1">
        <inertial>
            <origin xyz="0.0 0.0 0.0" rpy="0 0 0"/>
            <mass value="1" />
            <inertia ixx="100" ixy="0" ixz="0" iyy="100" iyz="0" izz="100" />
        </inertial>
        <visual>
            <origin xyz="0.0 0.0 0.0" rpy="0 0 0"/>
            <geometry>
                <box size="0.3442584316775972 0.20461878894430366 0.258075695532041" />
            </geometry>
            <material name="green">
                <color rgba="0 1.0 0 1.0"/>
            </material>
        </visual>
        <collision>
            <origin xyz="0.0 0.0 0.0" rpy="0 0 0"/>
            <geometry>
                <box size="0.3442584316775972 0.20461878894430366 0.258075695532041" />
            </geometry>
        </collision>
    </link>
    <link name="link2">
        <inertial>
            <origin xyz="0.15921010721699808 0.0 0.0" rpy="0 0 0"/>
            <mass value="1" />
            <inertia ixx="100" ixy="0" ixz="0" iyy="100" iyz="0" izz="100" />
        </inertial>
        <visual>
            <origin xyz="0.15921010721699808 0.0 0.0" rpy="0 0 0"/>
            <geometry>
                <box size="0.31842021443399615 0.25841683916880964 0.10802134308038686" />
            </geometry>
            <material name="green">
                <color rgba="0 1.0 0 1.0"/>
            </material>
        </visual>
        <collision>
            <origin xyz="0.15921010721699808 0.0 0.0" rpy="0 0 0"/>
            <geometry>
                <box size="0.31842021443399615 0.25841683916880964 0.10802134308038686" />
            </geometry>
        </collision>
    </link>
    <link name="link3">
        <inertial>
            <origin xyz="0.0 0.0 -0.14793465290345642" rpy="0 0 0"/>
            <mass value="1" />
            <inertia ixx="100" ixy="0" ixz="0" iyy="100" iyz="0" izz="100" />
        </inertial>
        <visual>
            <origin xyz="0.0 0.0 -0.14793465290345642" rpy="0 0 0"/>
            <geometry>
                <box size="0.17205954419060016 0.10803793516462923 0.29586930580691284" />
            </geometry>
            <material name="green">
                <color rgba="0 1.0 0 1.0"/>
            </material>
        </visual>
        <collision>
            <origin xyz="0.0 0.0 -0.14793465290345642" rpy="0 0 0"/>
            <geometry>
                <box size="0.17205954419060016 0.10803793516462923 0.29586930580691284" />
            </geometry>
        </collision>
    </link>
    <link name="link4">
        <inertial>
            <origin xyz="0.0 0.09032081434225372 0.0" rpy="0 0 0"/>
            <mass value="1" />
            <inertia ixx="100" ixy="0" ixz="0" iyy="100" iyz="0" izz="100" />
        </inertial>
        <visual>
            <origin xyz="0.0 0.09032081434225372 0.0" rpy="0 0 0"/>
            <geometry>
                <box size="0.21507601183552646 0.18064162868450745 0.3643059484436133" />
            </geometry>
            <material name="red">
                <color rgba="0 0 1.0 1.0"/>
            </material>
        </visual>
        <collision>
            <origin xyz="0.0 0.09032081434225372 0.0" rpy="0 0 0"/>
            <geometry>
                <box size="0.21507601183552646 0.18064162868450745 0.3643059484436133" />
            </geometry>
        </collision>
    </link>
    <joint name="link1_link2" type="revolute">
       <parent link="link1"/>
       <child  link="link2"/>
       <origin rpy="0 0 0" xyz="0.17214642876038247 0.0 0.0" />
       <axis xyz="0 1 0"/>
       <limit effort="0.0" lower="-3.14159" upper="3.14159" velocity="0.0"/>
    </joint>
    <joint name="link1_link3" type="revolute">
       <parent link="link1"/>
       <child  link="link3"/>
       <origin rpy="0 0 0" xyz="0.0 0.0 -0.12905075155079712" />
       <axis xyz="0 1 0"/>
       <limit effort="0.0" lower="-3.14159" upper="3.14159" velocity="0.0"/>
    </joint>
    <joint name="link2_link4" type="revolute">
       <parent link="link2"/>
       <child  link="link4"/>
       <origin rpy="0 0 0" xyz="0.15922602822771978 0.12922134042636327 0.0" />
       <axis xyz="0 0 1"/>
       <limit effort="0.0" lower="-3.14159" upper="3.14159" velocity="0.0"/>
    </joint>
</robot>